Workbook

Sheet Budget
B2: 品号 | C2: NPI Program Items | D2: 项目名称 | E2: 品牌名称 | I2: 备注
B3: RD-001 | C3: 样品费用 | D3: =#REF! -> #REF! | E3: Xiaomi | G3: 模具 | H3: 600000
B4: RD-002 | C4: 测试费用 | D4: =#REF! -> #REF! | E4: Xiaomi | G4: 治具 | H4: 715000
B5: RD-003 | C5: NPI试产样机费用 | D5: =#REF! -> #REF! | E5: Xiaomi | G5: 研发NRE | H5: =781250-H13 -> 481250
B6: RD-004 | C6: NPI试产服务费用 | D6: =#REF! -> #REF! | E6: Xiaomi | G6: 测试+其它 | H6: 159000
B7: RD-005 | C7: 试验模具治具 | D7: =#REF! -> #REF! | E7: Xiaomi | G7: 认证 | H7: 150000
B8: RD-006 | C8: 技术服务（委托研发） | D8: =#REF! -> #REF! | E8: Xiaomi | G8: 人力 | H8: =(127-50)*33000*0.8 -> 2032800 | I8: 原127 人月，10月前约50，转极印后压缩20%
B9: RD-007 | C9: 软件（研发） | D9: =#REF! -> #REF! | E9: Xiaomi | G9: 汇总 | H9: =SUM(H3:H8) -> 4138050
B10: RD-008 | C10: 咨询服务 | D10: =#REF! -> #REF! | E10: Xiaomi
B11: RD-009 | C11: 人力资源服务 | D11: =#REF! -> #REF! | E11: Xiaomi
B12: RD-011 | C12: 研发测试用耗材 | D12: =#REF! -> #REF! | E12: Xiaomi | G12: 右侧为沉没成本 | H12: =50*33000 -> 1650000
B13: ZC-1202 | C13: 生产模具 | D13: =#REF! -> #REF! | E13: Xiaomi | H13: 300000
B14: ZC-1202 | C14: 生产治具 | D14: =#REF! -> #REF! | E14: Xiaomi | H14: =H12+H13 -> 1950000
B15: ZC-1299 | C15: 其他生产设备 | D15: =#REF! -> #REF! | E15: Xiaomi
B16: ZC-1301 | C16: 办公计算机设备 | D16: =#REF! -> #REF! | E16: Xiaomi
B17: ZC-1302 | C17: 办公测试设备 | D17: =#REF! -> #REF! | E17: Xiaomi
B18: ZC-2201 | C18: 研发工具 | D18: =#REF! -> #REF! | E18: Xiaomi
B19: Travel-P | C19: 项目差旅费用 | D19: =#REF! -> #REF! | E19: Xiaomi
B20: Logistics-P | C20: 物流费用 | D20: =#REF! -> #REF! | E20: Xiaomi
B21: RCOW-P | C21: 项目人力费用 | D21: =#REF! -> #REF! | E21: Xiaomi
B22: TB-P | C22: 项目组团建费用 | D22: =#REF! -> #REF! | E22: Xiaomi
C24: Monthly Total
C26: Investment Total | D26: =SUM(#REF!) -> #REF!
B31: Ricotta-P 国内 | C31: 45587
B34: 品号 | C34: NPI Program Items | D34: 项目名称 | E34: 品牌名称
B35: RD-001 | C35: 样品费用 | D35: =#REF! -> #REF! | E35: Xiaomi
B36: RD-002 | C36: 测试费用 | D36: =#REF! -> #REF! | E36: Xiaomi
B37: RD-003 | C37: NPI试产样机费用 | D37: =#REF! -> #REF! | E37: Xiaomi
B38: RD-004 | C38: NPI试产服务费用 | D38: =#REF! -> #REF! | E38: Xiaomi
B39: RD-005 | C39: 试验模具治具 | D39: =#REF! -> #REF! | E39: Xiaomi
B40: RD-006 | C40: 技术服务（委托研发） | D40: =#REF! -> #REF! | E40: Xiaomi
B41: RD-007 | C41: 软件（研发） | D41: =#REF! -> #REF! | E41: Xiaomi
B42: RD-008 | C42: 咨询服务 | D42: =#REF! -> #REF! | E42: Xiaomi
B43: RD-009 | C43: 人力资源服务 | D43: =#REF! -> #REF! | E43: Xiaomi
B44: RD-011 | C44: 研发测试用耗材 | D44: =#REF! -> #REF! | E44: Xiaomi
B45: ZC-1202 | C45: 生产模具 | D45: =#REF! -> #REF! | E45: Xiaomi
B46: ZC-1202 | C46: 生产治具 | D46: =#REF! -> #REF! | E46: Xiaomi
... B54: TB-P | C54: 项目组团建费用 | D54: =#REF! -> #REF! | E54: Xiaomi
C56: Monthly Total
C58: Investment Total | D58: =SUM(#REF!) -> #REF!
...

Sheet 销量概率分布说明
B2: AiKen 销量概率分布 · 读数表
B3: 模型 v0.2 · 8,000 次蒙特卡洛 · 参数：参照类已校准，漏斗为行业通带占位（待市场部数据校准）
B5: 这个分布是什么？ | C5: 8,000 次模拟得到的「首年（或三年累计）销量」的全集。每次模拟 = 从参照类先验区间随机抽一组 (m·p·q) 跑一条 Bass 曲线。它不是正态分布——右尾更长（小概率卖出非常多），形状类似对数正态。
B6: 横轴 / 纵轴各是什么？ | C6: 横轴 = 销量（台）；纵轴 = 概率密度（落在这个销量区间的模拟次数占比）。曲线下总面积 = 100%。
B7: P5 / P50 / P95 是什么？ | C7: 分位数。P50 = 中位数：一半的模拟结果比它高、一半比它低（最可能的单点读数）。P5 = 只有 5% 的模拟比它更差（悲观边界）；P95 = 只有 5% 的模拟比它更好（乐观边界）。P5–P95 之间覆盖了 90% 的可能性，即「大概率区间」。
B8: 怎么读「达到某销量对应多少概率」？ | C8: 两种读法：① 找分位表中第一个 ≥ 该销量的行，其概率列即答案（近似）；② 直接查「关键概率」表——如 P(首年 ≥ 3.6万) 表示 8,000 次模拟中销量 ≥ 36,000 台的次数占比。注意：分位表给的是「多少分位对应多少销量」，关键概率表给的是「多少销量对应多少概率」，两者互为反查。
B9: 和三档场景（Worst/Normal/Best）什么关系？ | C9: 三档场景 = 分布上的分位锚，不是预测点：Worst（月销500→年6000）≈ P1 以下；Normal（月销1000→年1.2万）≈ P1；Best（月销3000→年3.6万）≈ P75。三档供供应链与财务执行使用；全分布才是决策工具（详见方法论说明页）。
B10: 为什么首年 P50（2.86万）比会议 Normal（1.2万）高？ | C10: 主要差异来自媒介预算假设：模型按上市前 6 个月 120–280 万投放测算（P50≈202万），而会议 Normal 按 2% 销售费用折算全年仅约 14 万。校准会已确认 2% 不够——预算口径待市场部确认后重跑 v0.3。
B11: 读数示例 | C11: 「首年销量 P50 = 28,600 台」→ 一半的可能性卖得比它多；「P(首年 ≥ 36,000) = 25.8%」→ 约四分之一的概率达到 Best 档；「三年累计 P95 = 158,000 台」→ 20 次里约有 1 次三年卖过 15.8 万台。

Sheet 分位表
B2: 销量分位表 · 首年 & 三年累计
B3: 读法：如「首年 P50 = 28,600」表示 50% 的模拟结果首年销量低于 28,600 台。淡黄行 = 会议三档场景锚。
B5: 分位 P(x) | C5: 首年销量（台） | D5: 首年销量（万台） | E5: 首年 ≥ 该销量的概率 | F5: 三年累计（台） | G5: 三年累计（万台） | H5: 三年 ≥ 该销量的概率 | I5: 备注
B6: P5 | C6: 15430 | D6: 1.54 | E6: 95.0% | F6: 28116 | G6: 2.81 | H6: 95.0%
B7: P10 | C7: 17758 | D7: 1.78 | E7: 90.0% | F7: 36322 | G7: 3.63 | H7: 90.0% | I7: Worst
B8: P15 | C8: 19411 | D8: 1.94 | E8: 85.0% | F8: 42944 | G8: 4.29 | H8: 85.0%
B9: P20 | C9: 20931 | D9: 2.09 | E9: 80.0% | F9: 48593 | G9: 4.86 | H9: 80.0%
B10: P25 | C10: 22268 | D10: 2.23 | E10: 75.0% | F10: 53648 | G10: 5.36 | H10: 75.0%
B11: P30 | C11: 23562 | D11: 2.36 | E11: 70.0% | F11: 58418 | G11: 5.84 | H11: 70.0%
B12: P35 | C12: 24782 | D12: 2.48 | E12: 65.0% | F12: 63103 | G12: 6.31 | H12: 65.0%
B13: P40 | C13: 26015 | D13: 2.6 | E13: 60.0% | F13: 67490 | G13: 6.75 | H13: 60.0%
B14: P45 | C14: 27255 | D14: 2.73 | E14: 55.0% | F14: 72083 | G14: 7.21 | H14: 55.0%
B15: P50 | C15: 28551 | D15: 2.86 | E15: 50.0% | F15: 76488 | G15: 7.65 | H15: 50.0% | I15: Nomal：中位线
B16: P55 | C16: 29873 | D16: 2.99 | E16: 45.0% | F16: 81267 | G16: 8.13 | H16: 45.0%
B17: P60 | C17: 31355 | D17: 3.14 | E17: 40.0% | F17: 86419 | G17: 8.64 | H17: 40.0%
B18: P65 | C18: 32883 | D18: 3.29 | E18: 35.0% | F18: 91892 | G18: 9.19 | H18: 35.0%
B19: P70 | C19: 34393 | D19: 3.44 | E19: 30.0% | F19: 98113 | G19: 9.81 | H19: 30.0%
B20: P75 | C20: 36273 | D20: 3.63 | E20: 25.0% | F20: 104938 | G20: 10.49 | H20: 25.0%
B21: P80 | C21: 38398 | D21: 3.84 | E21: 20.0% | F21: 113023 | G21: 11.3 | H21: 20.0%
B22: P85 | C22: 41006 | D22: 4.1 | E22: 15.0% | F22: 122653 | G22: 12.27 | H22: 15.0%
B23: P90 | C23: 44567 | D23: 4.46 | E23: 10.0% | F23: 135879 | G23: 13.59 | H23: 10.0% | I23: Best
B24: P95 | C24: 50078 | D24: 5.01 | E24: 5.0% | F24: 158039 | G24: 15.8 | H24: 5.0%
B26: 关键概率读数
B27: 问法 | C27: 首年 | D27: 三年累计
B28: P(≥ 6,000 台) — Worst 场景线 | C28: 99.9% | D28: 100.0%
B29: P(≥ 12,000 台) — Normal 场景线 | C29: 98.5% | D29: 99.5%
B30: P(≥ 36,000 台) — Best 场景线 | C30: 25.8% | D30: 90.2%
B31: P(≥ 50,000 台) | C31: 5.1% | D31: 78.7%
B32: P(≥ 100,000 台) — 十万台线 | C32: 0.0% | D32: 28.5%
B33: P(≥ 200,000 台) | C33: 0.0% | D33: 1.1%
B35: 注：本表由 v0.2 模拟结果（v02_results.npz）直接计算生成；v0.3 校准后数字将更新。

Sheet Scenarios
C2: Normal
C3: 年销 | D3: 月销 | E3: 描述
B4: 第一年 | C4: =D4*12 -> 28800 | D4: 2400 | E4: 线上渠道正常发挥（天猫/抖音/京东自营 + 达人分销）。 | F4: 单次MOQ 3000，每三个月做一批。
B5: 第二年 | C5: =D5*12 -> 28800 | D5: 2400
B6: 第三年 | C6: =D6*12 -> 28800 | D6: 2400
B7: 合计 | C7: =SUM(C4:C6) -> 86400
C10: Best
C11: 年销 | D11: 月销 | E11: 描述
B12: 第一年 | C12: =D12*12 -> 44400 | D12: 3700 | E12: 产品的仿胶卷卖点成为话题，得到市场接受，社媒有自来水传播。 | F12: Nomal *3
B13: 第二年 | C13: =D13*12 -> 44400 | D13: 3700
B14: 第三年 | C14: =D14*12 -> 44400 | D14: 3700
B15: 合计 | C15: =SUM(C12:C14) -> 133200
C18: Worst
C19: 年销 | D19: 月销 | E19: 描述
B20: 第一年 | C20: =D20*12 -> 18000 | D20: 1500 | E20: 纯冷启动、社媒无传播、只靠自然流量和照片机存量转化。 | F20: ROI保持为正
B21: 第二年 | C21: =D21*12 -> 18000 | D21: 1500
B22: 第三年 | C22: =D22*12 -> 18000 | D22: 1500
B23: 合计 | C23: =SUM(C20:C22) -> 54000

Sheet Reve per Price
C2: Worst | E2: Normal | G2: Best
C3: 含税(RMB) | D3: 不含税(RMB) | E3: 含税(RMB) | F3: 不含税(RMB) | G3: 含税(RMB) | H3: 不含税(RMB)
B4: 出厂价 | C4: 250 | D4: =C4/1.13 -> 221.23894 | E4: 250 | F4: =E4/1.13 -> 221.23894 | G4: 250 | H4: =G4/1.13 -> 221.23894
B5: 国内运费 | C5: 0.58 | D5: =C5/1.09 -> 0.53211009 | E5: 0.58 | F5: =E5/1.09 -> 0.53211009 | G5: 0.58 | H5: =G5/1.09 -> 0.53211009
B6: 模具工装治具摊销 | C6: ='Worst Secnario'!F7 -> 73.055556 | D6: =C6/1.13 -> 64.650934 | E6: ='Normal Secnario'!F7 -> 45.659722 | F6: =E6/1.13 -> 40.406834 | G6: ='Best Secnario'!F7 -> 29.617117 | H6: =G6/1.13 -> 26.209838
B8: 零售价 | C8: 599 | D8: =C8/1.13 -> 530.0885 | E8: 599 | F8: =E8/1.13 -> 530.0885 | G8: 599 | H8: =G8/1.13 -> 530.0885
B9: 线上官旗比例 | C9: 0.65 | E9: 0.65 | G9: 0.65
B10: 线上官旗折扣 | C10: 0.85 | E10: 0.85 | G10: 0.85
B11: 线上渠道比例 | C11: 0.3 | E11: 0.3 | G11: 0.3
B12: 线上渠道折扣 | C12: 0.75 | E12: 0.75 | G12: 0.75
B13: 线下渠道比例 | C13: 0.05 | E13: 0.05 | G13: 0.05
B14: 线下渠道折扣 | C14: 0.72 | E14: 0.72 | G14: 0.72
B15: 扣除渠道后ASP | C15: =C8*C11*C12+C8*C13*C14+C8*C9*C10 -> 487.2865 | D15: =C15/1.13 -> 431.22699 | E15: =E8*E11*E12+E8*E13*E14+E8*E9*E10 -> 487.2865 | F15: =E15/1.13 -> 431.22699 | G15: =G8*G11*G12+G8*G13*G14+G8*G9*G10 -> 487.2865 | H15: =G15/1.13 -> 431.22699
B16: 毛利 | C16: =C15-C4-C5-C6 -> 163.65094 | E16: =E15-E4-E5-E6 -> 191.04678 | G16: =G15-G4-G5-G6 -> 207.08938
B17: 毛利率 | C17: =C16/C15 -> 0.33584133 | E17: =E16/E15 -> 0.39206253 | G17: =G16/G15 -> 0.42498486

Sheet 定价测算
B3: 零售价 | C3: 渠道ASP | D3: 单台净利 | E3: 压力口径（佣金+营销） | F3: 回本所需月销（模型/压力）
B4: 499 | C4: 408 | D4: 117.6 元 | E4: 86.6 元 | F4: 1,194 / 1,647 台/月
B5: 599 | C5: 490 | D5: 188.8 元 | E5: 151.6 元 | F5: 746 / 940 台/月
B6: 649 | C6: 532 | D6: 224.4 元 | E6: 184.0 元 | F6: 628 / 774 台/月
B9: 499 在数学上锁死了项目：单台净利 118 元，回本需要 3 年均匀月销 1,194 台。即使在 Best 销量（51,600 台）下 499 也只有 +99 万（压力口径 -64 万）。降到 499 换不来足够的销量弹性来弥补单台利润损失 —— 这个品类的购买决策是“好不好玩/出不出片”，不是“省 100 块”。
B10: 竞争锚点清晰：Flashback V2 卖 749-799，instax mini12 约 600，Pal 629。599 正好卡在“拍立得主力价位带”，比直接竞品便宜 150-200，故事完整：“比 Flashback 便宜 200，传输快 3 倍，风格更多，玩法更丰富。”
B11: 品牌切换后的身份问题：499 会把 AiKen 定成“廉价玩具”，与柯达 Charmera（209 元）一类混同，反而削弱“胶卷仪式感”的情绪价值定位；599 保留“轻奢潮玩”的心理账户。
B12: 上探选项：首发期或Y2、Y3做礼盒（相机 + 相纸/打印机联动套装/联名挂绳）测试价格天花板 —— 富士 Instax 礼盒逻辑都验证过礼赠场景溢价，成本几乎不变，单台净利增加。若转化率好，主销版本可长期留在 599 用 618/双 11 做节奏。

Sheet Normal Secnario
B1: AiKen Normal Scenario
B3: 模具 | C3: =Budget!H3 -> 600000 | F3: YEAR 1 | H3: YEAR 2 | J3: YEAR 3 | M3: Normal
B4: 治具 | C4: =Budget!H4 -> 715000 | F4: 含税 | G4: 不含税 | H4: 含税 | I4: 不含税 | J4: 含税 | K4: 不含税 | N4: 主机（不含税）
B5: 研发NRE (含CCOW) | C5: =Budget!H5 -> 481250 | E5: MPC（出厂价） | F5: ='Reve per Price'!C4 -> 250 | G5: =F5/1.13 -> 221.23894 | H5: =F5*0.98 -> 245 | I5: =H5/1.13 -> 216.81416 | J5: =H5*0.98 -> 240.1 | K5: =J5/1.13 -> 212.47788 | M5: Hannto零售价 | N5: =G22 -> 431.22699
B6: 测试 | C6: =Budget!H6 -> 159000 | E6: Royalty, License, Usage/unit | F6: =$C$16+$C$17 -> 0 | G6: =F6 -> 0 | H6: =$C$16+$C$17 -> 0 | I6: =H6 -> 0 | J6: =$C$16+$C$17 -> 0 | K6: =J6 -> 0 | M6: Hannto毛利率 | N6: =(N5-N7)/N5 -> 0.4869548
B7: 认证 | C7: =Budget!H7 -> 150000 | E7: 模具治具摊销/unit | F7: =(C3+C4)/C20 -> 45.659722 | G7: =F7/1.13 -> 40.406834 | H7: 0 | I7: =H7/1.13 -> 0 | J7: 0 | K7: =J7/1.13 -> 0 | M7: MPC | N7: =G5 -> 221.23894
B8: 其他 | C8: =Budget!H8 -> 2032800 | E8: 研发费用摊销/unit | F8: =(C9-C3-C4)/C20 -> 98.022569 | G8: =F8/1.13 -> 86.745637 | H8: 0 | I8: =H8 -> 0 | J8: 0 | K8: =J8 -> 0 | M8: CPU
B9: 研发费用汇总 | C9: =SUM(C3:C8) -> 4138050 | E9: 物流（工厂到仓库）/unit | F9: 0 | G9: =F9/1.09 -> 0 | H9: =F9 -> 0 | I9: =H9/1.09 -> 0 | J9: =H9 -> 0 | K9: =J9/1.09 -> 0 | M9: Volumn （3years) | N9: =SUM(C20:C26) -> 86400
E10: 物流（仓库到用户）/unit | F10: 0.58 | G10: =F10/1.09 -> 0.53211009 | H10: =F10 -> 0.58 | I10: =H10/1.09 -> 0.53211009 | J10: =H10 -> 0.58 | K10: =J10/1.09 -> 0.53211009 | M10: Revenue | N10: =G28+I28+K28 -> 36369456
B11: Royalty（Airprint) | C11: 0 | E11: Logistics Cost | F11: =F10+F9 -> 0.58 | G11: =G10+G9 -> 0.53211009 | H11: =H10+H9 -> 0.58 | I11: =I10+I9 -> 0.53211009 | J11: =J10+J9 -> 0.58 | K11: =K10+K9 -> 0.53211009 | M11: GM | N11: =G23*G27+I23*I27+K23*K27 -> 17634164
B12: Royalty（GGS) | C12: 0 | E12: 汉图MOH比例 | F12: 0.05 | G12: =F12 -> 0.05 | H12: 0.05 | I12: =H12 -> 0.05 | J12: 0.05 | K12: =J12 -> 0.05 | M12: GM% | N12: =N11/N10 -> 0.48486191
B13: Royalty（Adobe) | C13: 0 | E13: 汉图MOH | F13: =F12*F5 -> 12.5 | G13: =F13 -> 12.5 | H13: =H12*H5 -> 12.25 | I13: =H13 -> 12.25 | J13: =J12*J5 -> 12.005 | K13: =J13 -> 12.005 | M13: Profit | N13: =G29+I29+K29 -> 107598.9
B14: Royalty（WPS) | C14: 0 | E14: 返修率 | F14: 0.017 | G14: =F14 -> 0.017 | H14: =F14 -> 0.017 | I14: =H14 -> 0.017 | J14: =F14 -> 0.017 | K14: =J14 -> 0.017 | M14: Profit % | N14: =N13/N10 -> 0.0029584962
B15: Royalty (Others) | C15: 0 | E15: 返修费用 | F15: =C28*F14 -> 4.25 | G15: =F15/1.13 -> 3.7610619 | H15: =H14*C28 -> 4.25 | I15: =H15/1.13 -> 3.7610619 | J15: =J14*C28 -> 4.25 | K15: =J15/1.13 -> 3.7610619 | M15: Investment | N15: =C9 -> 4138050
B16: Royalty (Total) | C16: =SUM(C11:C15) -> 0 | E16: Service Cost | F16: =F15 -> 4.25 | G16: =G15 -> 3.7610619 | H16: =H15 -> 4.25 | I16: =I15 -> 3.7610619 | J16: =J15 -> 4.25 | K16: =K15 -> 3.7610619 | M16: ROI | N16: =N13/N15 -> 0.02600232
B17: OS | C17: 0 | E17: 资金成本率 | F17: 0.005 | G17: 0.01 | H17: 0.005 | I17: 0.01 | J17: 0.005 | K17: 0.01
E18: 资金成本 | F18: =F5*F17 -> 1.25 | G18: =F18 -> 1.25 | H18: =H5*H17 -> 1.225 | I18: =H18 -> 1.225 | J18: =J5*J17 -> 1.2005 | K18: =J18 -> 1.2005
B19: 生态链单机 | E19: 销售费用% | F19: 0.3 | G19: 0.01 | H19: 0.3 | I19: 0.01 | J19: 0.3 | K19: 0.01
B20: 第一年销量（国内） | C20: =Scenarios!C4 -> 28800 | E20: 销售费用/unit | F20: =F19*F22 -> 146.18595 | G20: =F20 -> 146.18595 | H20: =H19*H22 -> 142.38023 | I20: =H20 -> 142.38023 | J20: =J19*J22 -> 139.53263 | K20: =J20 -> 139.53263
B21: 第二年销量（国内） | C21: =Scenarios!C5 -> 28800 | E21: Total COS | F21: =F5+F6++F7+F8+F11+F13+F16+F18+F20 -> 558.44824 | G21: =G5+G6++G7+G8+G11+G13+G16+G18+G20 -> 512.62053 | H21: =H5+H6++H7+H8+H11+H13+H16+H18+H20 -> 405.68523 | I21: =I5+I6++I7+I8+I11+I13+I16+I18+I20 -> 376.96256 | J21: =J5+J6++J7+J8+J11+J13+J16+J18+J20 -> 397.66813 | K21: =K5+K6++K7+K8+K11+K13+K16+K18+K20 -> 369.50917
B22: 第三年销量（国内） | C22: =Scenarios!C6 -> 28800 | E22: 收入 | F22: ='Reve per Price'!E15 -> 487.2865 | G22: =F22/1.13 -> 431.22699 | H22: =(F22-3)*0.98 -> 474.60077 | I22: =H22/1.13 -> 420.00068 | J22: =H22*0.98 -> 465.10875 | K22: =J22/1.13 -> 411.60067
E23: 毛利/unit（含税） | F23: =F22-F5 -> 237.2865 | G23: =G22-G5 -> 209.98805 | H23: =H22-H5 -> 229.60077 | I23: =I22-I5 -> 203.18652 | J23: =J22-J5 -> 225.00875 | K23: =K22-K5 -> 199.12279
B24: 第一年销量（海外） | C24: 0 | E24: 毛利率 | F24: =F23/F22 -> 0.4869548 | G24: =G23/G22 -> 0.4869548 | H24: =H23/H22 -> 0.48377665 | I24: =I23/I22 -> 0.48377665 | J24: =J23/J22 -> 0.48377665 | K24: =K23/K22 -> 0.48377665
B25: 第二年销量（海外） | C25: 0 | E25: 净利/unit（含税） | F25: =F22-F21 -> -71.161742 | G25: =G22-G21 -> -81.393539 | H25: =H22-H21 -> 68.915539 | I25: =I22-I21 -> 43.038119 | J25: =J22-J21 -> 67.440628 | K25: =K22-K21 -> 42.091493
B26: 第三年销量（海外） | C26: 0 | E26: 净利率 | F26: =F25/F22 -> -0.14603676 | G26: =G25/G22 -> -0.18874871 | H26: =H25/H22 -> 0.14520739 | I26: =I25/I22 -> 0.10247155 | J26: =J25/J22 -> 0.1449997 | K26: =K25/K22 -> 0.10226294
E27: Volumn | F27: =C20+C24 -> 28800 | G27: =F27 -> 28800 | H27: =C21+C25 -> 28800 | I27: =H27 -> 28800 | J27: =C22+C26 -> 28800 | K27: =J27 -> 28800
B28: 返修成本HW（含税） | C28: =F5 -> 250 | E28: 总收入 | F28: =F27*F22 -> 14033851 | G28: =G27*G22 -> 12419337 | H28: =H27*H22 -> 13668502 | I28: =I27*I22 -> 12096020 | J28: =J27*J22 -> 13395132 | K28: =K27*K22 -> 11854099
E29: 总净利 | F29: =F27*F25 -> -2049458.2 | G29: =G27*G25 -> -2344133.9 | H29: =H27*H25 -> 1984767.5 | I29: =I27*I25 -> 1239497.8 | J29: =J27*J25 -> 1942290.1 | K29: =K27*K25 -> 1212235

Sheet Best Secnario
B1: AiKen Best Scenario
B3: 模具 | C3: =Budget!H3 -> 600000 | F3: YEAR 1 | H3: YEAR 2 | J3: YEAR 3 | M3: Best
B4: 治具 | C4: =Budget!H4 -> 715000 | F4: 含税 | G4: 不含税 | H4: 含税 | I4: 不含税 | J4: 含税 | K4: 不含税 | N4: 主机（不含税）
B5: 研发NRE (含CCOW) | C5: =Budget!H5 -> 481250 | E5: MPC（出厂价） | F5: ='Reve per Price'!C4 -> 250 | G5: =F5/1.13 -> 221.23894 | H5: =F5*0.98 -> 245 | I5: =H5/1.13 -> 216.81416 | J5: =H5*0.98 -> 240.1 | K5: =J5/1.13 -> 212.47788 | M5: Hannto零售价 | N5: =G22 -> 431.22699
B6: 测试 | C6: =Budget!H6 -> 159000 | E6: Royalty, License, Usage/unit | F6: =$C$16+$C$17 -> 0 | G6: =F6 -> 0 | H6: =$C$16+$C$17 -> 0 | I6: =H6 -> 0 | J6: =$C$16+$C$17 -> 0 | K6: =J6 -> 0 | M6: Hannto毛利率 | N6: =(N5-N7)/N5 -> 0.4869548
B7: 认证 | C7: =Budget!H7 -> 150000 | E7: 模具治具摊销/unit | F7: =(C3+C4-D3)/C20 -> 29.617117 | G7: =F7/1.13 -> 26.209838 | H7: 0 | I7: =H7/1.13 -> 0 | J7: 0 | K7: =J7/1.13 -> 0 | M7: MPC | N7: =G5 -> 221.23894
B8: 其他 | C8: =Budget!H8 -> 2032800 | E8: 研发费用摊销/unit | F8: =(C9-C3-C4)/C20 -> 63.582207 | G8: =F8/1.13 -> 56.26744 | H8: 0 | I8: =H8 -> 0 | J8: 0 | K8: =J8 -> 0 | M8: CPU
B9: 研发费用汇总 | C9: =SUM(C3:C8) -> 4138050 | E9: 物流（工厂到仓库）/unit | F9: 0 | G9: =F9/1.09 -> 0 | H9: =F9 -> 0 | I9: =H9/1.09 -> 0 | J9: =H9 -> 0 | K9: =J9/1.09 -> 0 | M9: Volumn （3years) | N9: =SUM(C20:C26) -> 133200
E10: 物流（仓库到用户）/unit | F10: 0.58 | G10: =F10/1.09 -> 0.53211009 | H10: =F10 -> 0.58 | I10: =H10/1.09 -> 0.53211009 | J10: =H10 -> 0.58 | K10: =J10/1.09 -> 0.53211009 | M10: Revenue | N10: =G28+I28+K28 -> 56069578
B11: Royalty（Airprint) | C11: 0 | E11: Logistics Cost | F11: =F10+F9 -> 0.58 | G11: =G10+G9 -> 0.53211009 | H11: =H10+H9 -> 0.58 | I11: =I10+I9 -> 0.53211009 | J11: =J10+J9 -> 0.58 | K11: =K10+K9 -> 0.53211009 | M11: GM | N11: =G23*G27+I23*I27+K23*K27 -> 27186003
B12: Royalty（GGS) | C12: 0 | E12: 汉图MOH比例 | F12: 0.05 | G12: =F12 -> 0.05 | H12: 0.05 | I12: =H12 -> 0.05 | J12: 0.05 | K12: =J12 -> 0.05 | M12: GM% | N12: =N11/N10 -> 0.48486191
B13: Royalty（Adobe) | C13: 0 | E13: 汉图MOH | F13: =F12*F5 -> 12.5 | G13: =F13 -> 12.5 | H13: =H12*H5 -> 12.25 | I13: =H13 -> 12.25 | J13: =J12*J5 -> 12.005 | K13: =J13 -> 12.005 | M13: Profit | N13: =G29+I29+K29 -> 2149460.2
B14: Royalty（WPS) | C14: 0 | E14: 返修率 | F14: 0.017 | G14: =F14 -> 0.017 | H14: =F14 -> 0.017 | I14: =H14 -> 0.017 | J14: =F14 -> 0.017 | K14: =J14 -> 0.017 | M14: Profit % | N14: =N13/N10 -> 0.038335587
B15: Royalty (Others) | C15: 0 | E15: 返修费用 | F15: =C28*F14 -> 4.25 | G15: =F15/1.13 -> 3.7610619 | H15: =H14*C28 -> 4.25 | I15: =H15/1.13 -> 3.7610619 | J15: =J14*C28 -> 4.25 | K15: =J15/1.13 -> 3.7610619 | M15: Investment | N15: =C9 -> 4138050
B16: Royalty (Total) | C16: =SUM(C11:C15) -> 0 | E16: Service Cost | F16: =F15 -> 4.25 | G16: =G15 -> 3.7610619 | H16: =H15 -> 4.25 | I16: =I15 -> 3.7610619 | J16: =J15 -> 4.25 | K16: =K15 -> 3.7610619 | M16: ROI | N16: =N13/N15 -> 0.51943794
B17: OS | C17: 0 | E17: 资金成本率 | F17: 0.005 | G17: 0.01 | H17: 0.005 | I17: 0.01 | J17: 0.005 | K17: 0.01
E18: 资金成本 | F18: =F5*F17 -> 1.25 | G18: =F18 -> 1.25 | H18: =H5*H17 -> 1.225 | I18: =H18 -> 1.225 | J18: =J5*J17 -> 1.2005 | K18: =J18 -> 1.2005
B19: 生态链单机 | E19: 销售费用% | F19: 0.3 | G19: 0.01 | H19: 0.3 | I19: 0.01 | J19: 0.3 | K19: 0.01
B20: 第一年销量（国内） | C20: =Scenarios!C12 -> 44400 | E20: 销售费用/unit | F20: =F19*F22 -> 146.18595 | G20: =F20 -> 146.18595 | H20: =H19*H22 -> 142.38023 | I20: =H20 -> 142.38023 | J20: =J19*J22 -> 139.53263 | K20: =J20 -> 139.53263
B21: 第二年销量（国内） | C21: =Scenarios!C13 -> 44400 | E21: Total COS | F21: =F5+F6++F7+F8+F11+F13+F16+F18+F20 -> 507.96527 | G21: =G5+G6++G7+G8+G11+G13+G16+G18+G20 -> 467.94534 | H21: =H5+H6++H7+H8+H11+H13+H16+H18+H20 -> 405.68523 | I21: =I5+I6++I7+I8+I11+I13+I16+I18+I20 -> 376.96256 | J21: =J5+J6++J7+J8+J11+J13+J16+J18+J20 -> 397.66813 | K21: =K5+K6++K7+K8+K11+K13+K16+K18+K20 -> 369.50917
B22: 第三年销量（国内） | C22: =Scenarios!C14 -> 44400 | E22: 收入 | F22: ='Reve per Price'!G15 -> 487.2865 | G22: =F22/1.13 -> 431.22699 | H22: =(F22-3)*0.98 -> 474.60077 | I22: =H22/1.13 -> 420.00068 | J22: =H22*0.98 -> 465.10875 | K22: =J22/1.13 -> 411.60067
E23: 毛利/unit（含税） | F23: =F22-F5 -> 237.2865 | G23: =G22-G5 -> 209.98805 | H23: =H22-H5 -> 229.60077 | I23: =I22-I5 -> 203.18652 | J23: =J22-J5 -> 225.00875 | K23: =K22-K5 -> 199.12279
B24: 第一年销量（海外） | C24: 0 | E24: 毛利率 | F24: =F23/F22 -> 0.4869548 | G24: =G23/G22 -> 0.4869548 | H24: =H23/H22 -> 0.48377665 | I24: =I23/I22 -> 0.48377665 | J24: =J23/J22 -> 0.48377665 | K24: =K23/K22 -> 0.48377665
B25: 第二年销量（海外） | C25: 0 | E25: 净利/unit（含税） | F25: =F22-F21 -> -20.678774 | G25: =G22-G21 -> -36.718347 | H25: =H22-H21 -> 68.915539 | I25: =I22-I21 -> 43.038119 | J25: =J22-J21 -> 67.440628 | K25: =K22-K21 -> 42.091493
B26: 第三年销量（海外） | C26: 0 | E26: 净利率 | F26: =F25/F22 -> -0.042436584 | G26: =G25/G22 -> -0.085148536 | H26: =H25/H22 -> 0.14520739 | I26: =I25/I22 -> 0.10247155 | J26: =J25/J22 -> 0.1449997 | K26: =K25/K22 -> 0.10226294
E27: Volumn | F27: =C20+C24 -> 44400 | G27: =F27 -> 44400 | H27: =C21+C25 -> 44400 | I27: =H27 -> 44400 | J27: =C22+C26 -> 44400 | K27: =J27 -> 44400
B28: 返修成本HW（含税） | C28: =F5 -> 250 | E28: 总收入 | F28: =F27*F22 -> 21635521 | G28: =G27*G22 -> 19146478 | H28: =H27*H22 -> 21072274 | I28: =I27*I22 -> 18648030 | J28: =J27*J22 -> 20650829 | K28: =K27*K22 -> 18275070
E29: 总净利 | F29: =F27*F25 -> -918137.58 | G29: =G27*G25 -> -1630294.6 | H29: =H27*H25 -> 3059849.9 | I29: =I27*I25 -> 1910892.5 | J29: =J27*J25 -> 2994363.9 | K29: =K27*K25 -> 1868862.3

Sheet Worst Secnario
B1: AiKen Worst Scenario
B3: 模具 | C3: =Budget!H3 -> 600000 | F3: YEAR 1 | H3: YEAR 2 | J3: YEAR 3 | M3: Worst
B4: 治具 | C4: =Budget!H4 -> 715000 | F4: 含税 | G4: 不含税 | H4: 含税 | I4: 不含税 | J4: 含税 | K4: 不含税 | N4: 主机（不含税）
B5: 研发NRE (含CCOW) | C5: =Budget!H5 -> 481250 | E5: MPC（出厂价） | F5: ='Reve per Price'!C4 -> 250 | G5: =F5/1.13 -> 221.23894 | H5: =F5*0.98 -> 245 | I5: =H5/1.13 -> 216.81416 | J5: =H5*0.98 -> 240.1 | K5: =J5/1.13 -> 212.47788 | M5: Hannto零售价 | N5: =G22 -> 431.22699
B6: 测试 | C6: =Budget!H6 -> 159000 | E6: Royalty, License, Usage/unit | F6: =$C$16+$C$17 -> 0 | G6: =F6 -> 0 | H6: =$C$16+$C$17 -> 0 | I6: =H6 -> 0 | J6: =$C$16+$C$17 -> 0 | K6: =J6 -> 0 | M6: Hannto毛利率 | N6: =(N5-N7)/N5 -> 0.4869548
B7: 认证 | C7: =Budget!H7 -> 150000 | E7: 模具治具摊销/unit | F7: =(C3+C4-D3)/C20 -> 73.055556 | G7: =F7/1.13 -> 64.650934 | H7: 0 | I7: =H7/1.13 -> 0 | J7: 0 | K7: =J7/1.13 -> 0 | M7: MPC | N7: =G5 -> 221.23894
B8: 其他 | C8: =Budget!H8 -> 2032800 | E8: 研发费用摊销/unit | F8: =(C9-C3-C4)/C20 -> 156.83611 | G8: =F8/1.13 -> 138.79302 | H8: 0 | I8: =H8 -> 0 | J8: 0 | K8: =J8 -> 0 | M8: CPU
B9: 研发费用汇总 | C9: =SUM(C3:C8) -> 4138050 | E9: 物流（工厂到仓库）/unit | F9: 0 | G9: =F9/1.09 -> 0 | H9: =F9 -> 0 | I9: =H9/1.09 -> 0 | J9: =H9 -> 0 | K9: =J9/1.09 -> 0 | M9: Volumn （3years) | N9: =SUM(C20:C26) -> 54000
E10: 物流（仓库到用户）/unit | F10: 0.58 | G10: =F10/1.09 -> 0.53211009 | H10: =F10 -> 0.58 | I10: =H10/1.09 -> 0.53211009 | J10: =H10 -> 0.58 | K10: =J10/1.09 -> 0.53211009 | M10: Revenue | N10: =G28+I28+K28 -> 22730910
B11: Royalty（Airprint) | C11: 0 | E11: Logistics Cost | F11: =F10+F9 -> 0.58 | G11: =G10+G9 -> 0.53211009 | H11: =H10+H9 -> 0.58 | I11: =I10+I9 -> 0.53211009 | J11: =J10+J9 -> 0.58 | K11: =K10+K9 -> 0.53211009 | M11: GM | N11: =G23*G27+I23*I27+K23*K27 -> 11021353
B12: Royalty（GGS) | C12: 0 | E12: 汉图MOH比例 | F12: 0.05 | G12: =F12 -> 0.05 | H12: 0.05 | I12: =H12 -> 0.05 | J12: 0.05 | K12: =J12 -> 0.05 | M12: GM% | N12: =N11/N10 -> 0.48486191
B13: Royalty（Adobe) | C13: 0 | E13: 汉图MOH | F13: =F12*F5 -> 12.5 | G13: =F13 -> 12.5 | H13: =H12*H5 -> 12.25 | I13: =H13 -> 12.25 | J13: =J12*J5 -> 12.005 | K13: =J13 -> 12.005 | M13: Profit | N13: =G29+I29+K29 -> -1305997.4
B14: Royalty（WPS) | C14: 0 | E14: 返修率 | F14: 0.017 | G14: =F14 -> 0.017 | H14: =F14 -> 0.017 | I14: =H14 -> 0.017 | J14: =F14 -> 0.017 | K14: =J14 -> 0.017 | M14: Profit % | N14: =N13/N10 -> -0.057454689
B15: Royalty (Others) | C15: 0 | E15: 返修费用 | F15: =C28*F14 -> 4.25 | G15: =F15/1.13 -> 3.7610619 | H15: =H14*C28 -> 4.25 | I15: =H15/1.13 -> 3.7610619 | J15: =J14*C28 -> 4.25 | K15: =J15/1.13 -> 3.7610619 | M15: Investment | N15: =C9 -> 4138050
B16: Royalty (Total) | C16: =SUM(C11:C15) -> 0 | E16: Service Cost | F16: =F15 -> 4.25 | G16: =G15 -> 3.7610619 | H16: =H15 -> 4.25 | I16: =I15 -> 3.7610619 | J16: =J15 -> 4.25 | K16: =K15 -> 3.7610619 | M16: ROI | N16: =N13/N15 -> -0.31560696
B17: OS | C17: 0 | E17: 资金成本率 | F17: 0.005 | G17: 0.01 | H17: 0.005 | I17: 0.01 | J17: 0.005 | K17: 0.01
E18: 资金成本 | F18: =F5*F17 -> 1.25 | G18: =F18 -> 1.25 | H18: =H5*H17 -> 1.225 | I18: =H18 -> 1.225 | J18: =J5*J17 -> 1.2005 | K18: =J18 -> 1.2005
B19: 生态链单机 | E19: 销售费用% | F19: 0.3 | G19: 0.01 | H19: 0.3 | I19: 0.01 | J19: 0.3 | K19: 0.01
B20: 第一年销量（国内） | C20: =Scenarios!C20 -> 18000 | E20: 销售费用/unit | F20: =F19*F22 -> 146.18595 | G20: =F20 -> 146.18595 | H20: =H19*H22 -> 142.38023 | I20: =H20 -> 142.38023 | J20: =J19*J22 -> 139.53263 | K20: =J20 -> 139.53263
B21: 第二年销量（国内） | C21: =Scenarios!C21 -> 18000 | E21: Total COS | F21: =F5+F6++F7+F8+F11+F13+F16+F18+F20 -> 644.65762 | G21: =G5+G6++G7+G8+G11+G13+G16+G18+G20 -> 588.91201 | H21: =H5+H6++H7+H8+H11+H13+H16+H18+H20 -> 405.68523 | I21: =I5+I6++I7+I8+I11+I13+I16+I18+I20 -> 376.96256 | J21: =J5+J6++J7+J8+J11+J13+J16+J18+J20 -> 397.66813 | K21: =K5+K6++K7+K8+K11+K13+K16+K18+K20 -> 369.50917
B22: 第三年销量（国内） | C22: =Scenarios!C22 -> 18000 | E22: 收入 | F22: ='Reve per Price'!C15 -> 487.2865 | G22: =F22/1.13 -> 431.22699 | H22: =(F22-3)*0.98 -> 474.60077 | I22: =H22/1.13 -> 420.00068 | J22: =H22*0.98 -> 465.10875 | K22: =J22/1.13 -> 411.60067
E23: 毛利/unit（含税） | F23: =F22-F5 -> 237.2865 | G23: =G22-G5 -> 209.98805 | H23: =H22-H5 -> 229.60077 | I23: =I22-I5 -> 203.18652 | J23: =J22-J5 -> 225.00875 | K23: =K22-K5 -> 199.12279
B24: 第一年销量（海外） | C24: 0 | E24: 毛利率 | F24: =F23/F22 -> 0.4869548 | G24: =G23/G22 -> 0.4869548 | H24: =H23/H22 -> 0.48377665 | I24: =I23/I22 -> 0.48377665 | J24: =J23/J22 -> 0.48377665 | K24: =K23/K22 -> 0.48377665
B25: 第二年销量（海外） | C25: 0 | E25: 净利/unit（含税） | F25: =F22-F21 -> -157.37112 | G25: =G22-G21 -> -157.68502 | H25: =H22-H21 -> 68.915539 | I25: =I22-I21 -> 43.038119 | J25: =J22-J21 -> 67.440628 | K25: =K22-K21 -> 42.091493
B26: 第三年销量（海外） | C26: 0 | E26: 净利率 | F26: =F25/F22 -> -0.32295398 | G26: =G25/G22 -> -0.36566594 | H26: =H25/H22 -> 0.14520739 | I26: =I25/I22 -> 0.10247155 | J26: =J25/J22 -> 0.1449997 | K26: =K25/K22 -> 0.10226294
E27: Volumn | F27: =C20+C24 -> 18000 | G27: =F27 -> 18000 | H27: =C21+C25 -> 18000 | I27: =H27 -> 18000 | J27: =C22+C26 -> 18000 | K27: =J27 -> 18000
B28: 返修成本HW（含税） | C28: =F5 -> 250 | E28: 总收入 | F28: =F27*F22 -> 8771157 | G28: =G27*G22 -> 7762085.8 | H28: =H27*H22 -> 8542813.9 | I28: =I27*I22 -> 7560012.3 | J28: =J27*J22 -> 8371957.6 | K28: =K27*K22 -> 7408812
E29: 总净利 | F29: =F27*F25 -> -2832680.1 | G29: =G27*G25 -> -2838330.4 | H29: =H27*H25 -> 1240479.7 | I29: =I27*I25 -> 774686.14 | J29: =J27*J25 -> 1213931.3 | K29: =K27*K25 -> 757646.88
