Workbook

Sheet Budget
B2: 品号 | C2: NPI Program Items | D2: 项目名称 | E2: 品牌名称 | I2: 备注
B3: RD-001 | C3: 样品费用 | D3: =#REF! -> #REF! | E3: Xiaomi | G3: 模具 | H3: 600000
B4: RD-002 | C4: 测试费用 | D4: =#REF! -> #REF! | E4: Xiaomi | G4: 治具 | H4: 500000
B5: RD-003 | C5: NPI试产样机费用 | D5: =#REF! -> #REF! | E5: Xiaomi | G5: 研发NRE | H5: 375550
B6: RD-004 | C6: NPI试产服务费用 | D6: =#REF! -> #REF! | E6: Xiaomi | G6: 测试+其它 | H6: 145000
B7: RD-005 | C7: 试验模具治具 | D7: =#REF! -> #REF! | E7: Xiaomi | G7: 认证 | H7: 150000
B8: RD-006 | C8: 技术服务（委托研发） | D8: =#REF! -> #REF! | E8: Xiaomi | G8: 人力 | H8: =(127-37)*33000 -> 2970000 | I8: 原127 人月，10月前约37
B9: RD-007 | C9: 软件（研发） | D9: =#REF! -> #REF! | E9: Xiaomi | G9: 汇总 | H9: =SUM(H3:H8) -> 4740550
B10: RD-008 | C10: 咨询服务 | D10: =#REF! -> #REF! | E10: Xiaomi
B11: RD-009 | C11: 人力资源服务 | D11: =#REF! -> #REF! | E11: Xiaomi
B12: RD-011 | C12: 研发测试用耗材 | D12: =#REF! -> #REF! | E12: Xiaomi | G12: 右侧为沉没成本 | H12: =37*33000 -> 1221000 | I12: 10月前人月
B13: ZC-1202 | C13: 生产模具 | D13: =#REF! -> #REF! | E13: Xiaomi | H13: 634700 | I13: 已发生NRE
B14: ZC-1202 | C14: 生产治具 | D14: =#REF! -> #REF! | E14: Xiaomi | H14: =H12+H13 -> 1855700 | I14: 沉没成本总和
B15: ZC-1299 | C15: 其他生产设备 | D15: =#REF! -> #REF! | E15: Xiaomi
B16: ZC-1301 | C16: 办公计算机设备 | D16: =#REF! -> #REF! | E16: Xiaomi
B17: ZC-1302 | C17: 办公测试设备 | D17: =#REF! -> #REF! | E17: Xiaomi
B18: ZC-2201 | C18: 研发工具 | D18: =#REF! -> #REF! | E18: Xiaomi
B19: Travel-P | C19: 项目差旅费用 | D19: =#REF! -> #REF! | E19: Xiaomi
B20: Logistics-P | C20: 物流费用 | D20: =#REF! -> #REF! | E20: Xiaomi
B21: RCOW-P | C21: 项目人力费用 | D21: =#REF! -> #REF! | E21: Xiaomi
B22: TB-P | C22: 项目组团建费用 | D22: =#REF! -> #REF! | E22: Xiaomi
C24: Monthly Total
C26: Investment Total | D26: =SUM(#REF!) -> #REF!
B31: Ricotta-P 国内 | C31: 45587
B34: 品号 | C34: NPI Program Items | D34: 项目名称 | E34: 品牌名称
B35: RD-001 | C35: 样品费用 | D35: =#REF! -> #REF! | E35: Xiaomi
B36: RD-002 | C36: 测试费用 | D36: =#REF! -> #REF! | E36: Xiaomi
B37: RD-003 | C37: NPI试产样机费用 | D37: =#REF! -> #REF! | E37: Xiaomi
B38: RD-004 | C38: NPI试产服务费用 | D38: =#REF! -> #REF! | E38: Xiaomi
B39: RD-005 | C39: 试验模具治具 | D39: =#REF! -> #REF! | E39: Xiaomi
B40: RD-006 | C40: 技术服务（委托研发） | D40: =#REF! -> #REF! | E40: Xiaomi
B41: RD-007 | C41: 软件（研发） | D41: =#REF! -> #REF! | E41: Xiaomi
B42: RD-008 | C42: 咨询服务 | D42: =#REF! -> #REF! | E42: Xiaomi
B43: RD-009 | C43: 人力资源服务 | D43: =#REF! -> #REF! | E43: Xiaomi
B44: RD-011 | C44: 研发测试用耗材 | D44: =#REF! -> #REF! | E44: Xiaomi
B45: ZC-1202 | C45: 生产模具 | D45: =#REF! -> #REF! | E45: Xiaomi
B46: ZC-1202 | C46: 生产治具 | D46: =#REF! -> #REF! | E46: Xiaomi
... B54: TB-P | C54: 项目组团建费用 | D54: =#REF! -> #REF! | E54: Xiaomi
C56: Monthly Total
C58: Investment Total | D58: =SUM(#REF!) -> #REF!
...

Sheet BOM&ASP
C2: ASP | F2: BOM
B3: 零售价 | C3: 699 | D3: =C3/1.13 -> 618.58407 | F3: 250
B4: 线上官旗比例 | C4: 0.65
B5: 线上官旗折扣 | C5: 0.85
B6: 线上渠道比例 | C6: 0.3
B7: 线上渠道折扣 | C7: 0.75
B8: 线下渠道比例 | C8: 0.05
B9: 线下渠道折扣 | C9: 0.72
B10: 扣除渠道后ASP | C10: =C3*C6*C7+C3*C8*C9+C3*C4*C5 -> 568.6365 | D10: =C10/1.13 -> 503.21814

Sheet 分位表
B2: 销量分位表 · 首年 & 三年累计
B3: 读法：如「首年 P50 = 22,123」表示 50% 的模拟结果首年销量低于 22,123 台。
B5: 分位 P(x) | C5: 首年销量（台） | D5: 首年销量（万台） | E5: 首年 ≥ 该销量的概率 | F5: 三年累计（台） | G5: 三年累计（万台） | H5: 三年 ≥ 该销量的概率 | I5: 备注
B6: P5 | C6: 12802 | D6: 1.28 | E6: 95% | F6: 26994 | G6: 2.7 | H6: 95%
B7: P10 | C7: 14560 | D7: 1.46 | E7: 90% | F7: 33818 | G7: 3.38 | H7: 90%
B8: P15 | C8: 15749 | D8: 1.57 | E8: 85% | F8: 38762 | G8: 3.88 | H8: 85%
B9: P20 | C9: 16844 | D9: 1.68 | E9: 80% | F9: 43038 | G9: 4.3 | H9: 80% | I9: Worst 场景锚（月销 ≈ 1,200）
B10: P25 | C10: 17814 | D10: 1.78 | E10: 75% | F10: 46691 | G10: 4.67 | H10: 75%
B11: P30 | C11: 18722 | D11: 1.87 | E11: 70% | F11: 50252 | G11: 5.03 | H11: 70%
B12: P35 | C12: 19575 | D12: 1.96 | E12: 65% | F12: 53567 | G12: 5.36 | H12: 65%
B13: P40 | C13: 20417 | D13: 2.04 | E13: 60% | F13: 57151 | G13: 5.72 | H13: 60%
B14: P45 | C14: 21323 | D14: 2.13 | E14: 55% | F14: 60448 | G14: 6.04 | H14: 55%
B15: P50 | C15: 22123 | D15: 2.21 | E15: 50% | F15: 63831 | G15: 6.38 | H15: 50% | I15: Normal 场景锚（月销 ≈ 1,800）
B16: P55 | C16: 23071 | D16: 2.31 | E16: 45% | F16: 67315 | G16: 6.73 | H16: 45%
B17: P60 | C17: 24035 | D17: 2.4 | E17: 40% | F17: 70828 | G17: 7.08 | H17: 40%
B18: P65 | C18: 25058 | D18: 2.51 | E18: 35% | F18: 74802 | G18: 7.48 | H18: 35%
B19: P70 | C19: 26081 | D19: 2.61 | E19: 30% | F19: 79059 | G19: 7.91 | H19: 30%
B20: P75 | C20: 27283 | D20: 2.73 | E20: 25% | F20: 83983 | G20: 8.4 | H20: 25%
B21: P80 | C21: 28721 | D21: 2.87 | E21: 20% | F21: 89343 | G21: 8.93 | H21: 20%
B22: P85 | C22: 30500 | D22: 3.05 | E22: 15% | F22: 96544 | G22: 9.65 | H22: 15%
B23: P90 | C23: 32793 | D23: 3.28 | E23: 10% | F23: 106182 | G23: 10.62 | H23: 10% | I23: Best 场景锚（月销 ≈ 3,000）
B24: P95 | C24: 36294 | D24: 3.63 | E24: 5% | F24: 120877 | G24: 12.09 | H24: 5%

Sheet Scenarios
C2: Normal
C3: 年销 | D3: 月销 | E3: 分布
B4: 第一年 | C4: =D4*12 -> 21600 | D4: 1800 | E4: P50
B5: 第二年 | C5: =D5*12 -> 21600 | D5: 1800
B6: 第三年 | C6: =D6*12 -> 21600 | D6: 1800
B7: 合计 | C7: =SUM(C4:C6) -> 64800
C10: Best
C11: 年销 | D11: 月销 | E11: 分布
B12: 第一年 | C12: =D12*12 -> 36000 | D12: 3000 | E12: P90
B13: 第二年 | C13: =D13*12 -> 36000 | D13: 3000
B14: 第三年 | C14: =D14*12 -> 36000 | D14: 3000
B15: 合计 | C15: =SUM(C12:C14) -> 108000
C18: Worst
C19: 年销 | D19: 月销 | E19: 分布
B20: 第一年 | C20: =D20*12 -> 14400 | D20: 1200 | E20: P20
B21: 第二年 | C21: =D21*12 -> 14400 | D21: 1200
B22: 第三年 | C22: =D22*12 -> 14400 | D22: 1200
B23: 合计 | C23: =SUM(C20:C22) -> 43200

Sheet 财务读数
A1: AiKen 699 财务读数
B2: Worst (P10) | C2: Normal (P50) | D2: Best (P90)
A3: Hannto零售价 | B3: 503.21814 | C3: 503.21814 | D3: 503.21814
A4: Hannto毛利率 | B4: 0.56035182 | C4: 0.56035182 | D4: 0.56035182
A5: MPC | B5: 221.23894 | C5: 221.23894 | D5: 221.23894
A6: CPU
A7: Volumn （3years) | B7: 43200 | C7: 64800 | D7: 108000
A8: Revenue | B8: 21232960 | C8: 31849440 | D8: 53082400
A9: GM | B9: 11865314 | C9: 17797971 | D9: 29663285
A10: GM% | B10: 0.55881582 | C10: 0.55881582 | D10: 0.55881582
A11: Profit | B11: -295500.6 | C11: 1654337.6 | D11: 5554014
A12: Profit % | B12: -0.013917071 | C12: 0.051942439 | D12: 0.10463005
A13: Investment | B13: 4740550 | C13: 4740550 | D13: 4740550
A14: ROI | B14: -0.062334667 | C14: 0.34897588 | D14: 1.171597

Sheet Normal Secnario
B1: AiKen Normal Scenario
B3: 模具 | C3: =Budget!H3 -> 600000 | F3: YEAR 1 | H3: YEAR 2 | J3: YEAR 3 | M3: Normal
B4: 治具 | C4: =Budget!H4 -> 500000 | F4: 含税 | G4: 不含税 | H4: 含税 | I4: 不含税 | J4: 含税 | K4: 不含税 | N4: 主机（不含税）
B5: 研发NRE (含CCOW) | C5: =Budget!H5 -> 375550 | E5: MPC（出厂价） | F5: ='BOM&ASP'!F3 -> 250 | G5: =F5/1.13 -> 221.23894 | H5: =F5*0.98 -> 245 | I5: =H5/1.13 -> 216.81416 | J5: =H5*0.98 -> 240.1 | K5: =J5/1.13 -> 212.47788 | M5: Hannto零售价 | N5: =G22 -> 503.21814
B6: 测试 | C6: =Budget!H6 -> 145000 | E6: Royalty, License, Usage/unit | F6: =$C$16+$C$17 -> 0 | G6: =F6 -> 0 | H6: =$C$16+$C$17 -> 0 | I6: =H6 -> 0 | J6: =$C$16+$C$17 -> 0 | K6: =J6 -> 0 | M6: Hannto毛利率 | N6: =(N5-N7)/N5 -> 0.56035182
B7: 认证 | C7: =Budget!H7 -> 150000 | E7: 模具治具摊销/unit | F7: =(C3+C4)/C20 -> 50.925926 | G7: =F7/1.13 -> 45.067191 | H7: 0 | I7: =H7/1.13 -> 0 | J7: 0 | K7: =J7/1.13 -> 0 | M7: MPC | N7: =G5 -> 221.23894
B8: 其他 | C8: =Budget!H8 -> 2970000 | E8: 研发费用摊销/unit | F8: =(C9-C3-C4)/C20 -> 168.54398 | G8: =F8/1.13 -> 149.15397 | H8: 0 | I8: =H8 -> 0 | J8: 0 | K8: =J8 -> 0 | M8: CPU
B9: 研发费用汇总 | C9: =SUM(C3:C8) -> 4740550 | E9: 物流（工厂到仓库）/unit | F9: 0 | G9: =F9/1.09 -> 0 | H9: =F9 -> 0 | I9: =H9/1.09 -> 0 | J9: =H9 -> 0 | K9: =J9/1.09 -> 0 | M9: Volumn （3years) | N9: =SUM(C20:C26) -> 64800
E10: 物流（仓库到用户）/unit | F10: 0.58 | G10: =F10/1.09 -> 0.53211009 | H10: =F10 -> 0.58 | I10: =H10/1.09 -> 0.53211009 | J10: =H10 -> 0.58 | K10: =J10/1.09 -> 0.53211009 | M10: Revenue | N10: =G28+I28+K28 -> 31849440
B11: Royalty（Airprint) | C11: 0 | E11: Logistics Cost | F11: =F10+F9 -> 0.58 | G11: =G10+G9 -> 0.53211009 | H11: =H10+H9 -> 0.58 | I11: =I10+I9 -> 0.53211009 | J11: =J10+J9 -> 0.58 | K11: =K10+K9 -> 0.53211009 | M11: GM | N11: =G23*G27+I23*I27+K23*K27 -> 17797971
B12: Royalty（GGS) | C12: 0 | E12: 汉图MOH比例 | F12: 0.05 | G12: =F12 -> 0.05 | H12: 0.05 | I12: =H12 -> 0.05 | J12: 0.05 | K12: =J12 -> 0.05 | M12: GM% | N12: =N11/N10 -> 0.55881582
B13: Royalty（Adobe) | C13: 0 | E13: 汉图MOH | F13: =F12*F5 -> 12.5 | G13: =F13 -> 12.5 | H13: =H12*H5 -> 12.25 | I13: =H13 -> 12.25 | J13: =J12*J5 -> 12.005 | K13: =J13 -> 12.005 | M13: Profit | N13: =G29+I29+K29 -> 1654337.6
B14: Royalty（WPS) | C14: 0 | E14: 返修率 | F14: 0.017 | G14: =F14 -> 0.017 | H14: =F14 -> 0.017 | I14: =H14 -> 0.017 | J14: =F14 -> 0.017 | K14: =J14 -> 0.017 | M14: Profit % | N14: =N13/N10 -> 0.051942439
B15: Royalty (Others) | C15: 0 | E15: 返修费用 | F15: =C28*F14 -> 4.25 | G15: =F15/1.13 -> 3.7610619 | H15: =H14*C28 -> 4.25 | I15: =H15/1.13 -> 3.7610619 | J15: =J14*C28 -> 4.25 | K15: =J15/1.13 -> 3.7610619 | M15: Investment | N15: =C9 -> 4740550
B16: Royalty (Total) | C16: =SUM(C11:C15) -> 0 | E16: Service Cost | F16: =F15 -> 4.25 | G16: =G15 -> 3.7610619 | H16: =H15 -> 4.25 | I16: =I15 -> 3.7610619 | J16: =J15 -> 4.25 | K16: =K15 -> 3.7610619 | M16: ROI | N16: =N13/N15 -> 0.34897588
B17: OS | C17: 0 | E17: 资金成本率 | F17: 0.005 | G17: 0.01 | H17: 0.005 | I17: 0.01 | J17: 0.005 | K17: 0.01
E18: 资金成本 | F18: =F5*F17 -> 1.25 | G18: =F18 -> 1.25 | H18: =H5*H17 -> 1.225 | I18: =H18 -> 1.225 | J18: =J5*J17 -> 1.2005 | K18: =J18 -> 1.2005
B19: 生态链单机 | E19: 销售费用% | F19: 0.3 | G19: 0.01 | H19: 0.3 | I19: 0.01 | J19: 0.3 | K19: 0.01
B20: 第一年销量（国内） | C20: =Scenarios!C4 -> 21600 | E20: 销售费用/unit | F20: =F19*F22 -> 170.59095 | G20: =F20 -> 170.59095 | H20: =H19*H22 -> 166.29713 | I20: =H20 -> 166.29713 | J20: =J19*J22 -> 162.97119 | K20: =J20 -> 162.97119 | M20: =F20*C20+H20*C21+J20*C22 -> 10796960
B21: 第二年销量（国内） | C21: =Scenarios!C5 -> 21600 | E21: Total COS | F21: =F5+F6++F7+F8+F11+F13+F16+F18+F20 -> 658.64086 | G21: =G5+G6++G7+G8+G11+G13+G16+G18+G20 -> 604.09422 | H21: =H5+H6++H7+H8+H11+H13+H16+H18+H20 -> 429.60213 | I21: =I5+I6++I7+I8+I11+I13+I16+I18+I20 -> 400.87946 | J21: =J5+J6++J7+J8+J11+J13+J16+J18+J20 -> 421.10669 | K21: =K5+K6++K7+K8+K11+K13+K16+K18+K20 -> 392.94774
B22: 第三年销量（国内） | C22: =Scenarios!C6 -> 21600 | E22: 收入 | F22: ='BOM&ASP'!C10 -> 568.6365 | G22: =F22/1.13 -> 503.21814 | H22: =(F22-3)*0.98 -> 554.32377 | I22: =H22/1.13 -> 490.55201 | J22: =H22*0.98 -> 543.23729 | K22: =J22/1.13 -> 480.74097
E23: 毛利/unit（含税） | F23: =F22-F5 -> 318.6365 | G23: =G22-G5 -> 281.9792 | H23: =H22-H5 -> 309.32377 | I23: =I22-I5 -> 273.73785 | J23: =J22-J5 -> 303.13729 | K23: =K22-K5 -> 268.26309
B24: 第一年销量（海外） | C24: 0 | E24: 毛利率 | F24: =F23/F22 -> 0.56035182 | G24: =G23/G22 -> 0.56035182 | H24: =H23/H22 -> 0.55802004 | I24: =I23/I22 -> 0.55802004 | J24: =J23/J22 -> 0.55802004 | K24: =K23/K22 -> 0.55802004
B25: 第二年销量（海外） | C25: 0 | E25: 净利/unit（含税） | F25: =F22-F21 -> -90.004357 | G25: =G22-G21 -> -100.87608 | H25: =H22-H21 -> 124.72164 | I25: =I22-I21 -> 89.672547 | J25: =J22-J21 -> 122.13061 | K25: =K22-K21 -> 87.793232
B26: 第三年销量（海外） | C26: 0 | E26: 净利率 | F26: =F25/F22 -> -0.15828101 | G26: =G25/G22 -> -0.20046192 | H26: =H25/H22 -> 0.22499782 | I26: =I25/I22 -> 0.18279926 | J26: =J25/J22 -> 0.22482 | K26: =K25/K22 -> 0.18262066
E27: Volumn | F27: =C20+C24 -> 21600 | G27: =F27 -> 21600 | H27: =C21+C25 -> 21600 | I27: =H27 -> 21600 | J27: =C22+C26 -> 21600 | K27: =J27 -> 21600
B28: 返修成本HW（含税） | C28: =F5 -> 250 | E28: 总收入 | F28: =F27*F22 -> 12282548 | G28: =G27*G22 -> 10869512 | H28: =H27*H22 -> 11973393 | I28: =I27*I22 -> 10595923 | J28: =J27*J22 -> 11733926 | K28: =K27*K22 -> 10384005
E29: 总净利 | F29: =F27*F25 -> -1944094.1 | G29: =G27*G25 -> -2178923.2 | H29: =H27*H25 -> 2693987.4 | I29: =I27*I25 -> 1936927 | J29: =J27*J25 -> 2638021.1 | K29: =K27*K25 -> 1896333.8

Sheet Best Secnario
B1: AiKen Best Scenario
B3: 模具 | C3: =Budget!H3 -> 600000 | F3: YEAR 1 | H3: YEAR 2 | J3: YEAR 3 | M3: Best
B4: 治具 | C4: =Budget!H4 -> 500000 | F4: 含税 | G4: 不含税 | H4: 含税 | I4: 不含税 | J4: 含税 | K4: 不含税 | N4: 主机（不含税）
B5: 研发NRE (含CCOW) | C5: =Budget!H5 -> 375550 | E5: MPC（出厂价） | F5: ='BOM&ASP'!F3 -> 250 | G5: =F5/1.13 -> 221.23894 | H5: =F5*0.98 -> 245 | I5: =H5/1.13 -> 216.81416 | J5: =H5*0.98 -> 240.1 | K5: =J5/1.13 -> 212.47788 | M5: Hannto零售价 | N5: =G22 -> 503.21814
B6: 测试 | C6: =Budget!H6 -> 145000 | E6: Royalty, License, Usage/unit | F6: =$C$16+$C$17 -> 0 | G6: =F6 -> 0 | H6: =$C$16+$C$17 -> 0 | I6: =H6 -> 0 | J6: =$C$16+$C$17 -> 0 | K6: =J6 -> 0 | M6: Hannto毛利率 | N6: =(N5-N7)/N5 -> 0.56035182
B7: 认证 | C7: =Budget!H7 -> 150000 | E7: 模具治具摊销/unit | F7: =(C3+C4-D3)/C20 -> 30.555556 | G7: =F7/1.13 -> 27.040315 | H7: 0 | I7: =H7/1.13 -> 0 | J7: 0 | K7: =J7/1.13 -> 0 | M7: MPC | N7: =G5 -> 221.23894
B8: 其他 | C8: =Budget!H8 -> 2970000 | E8: 研发费用摊销/unit | F8: =(C9-C3-C4)/C20 -> 101.12639 | G8: =F8/1.13 -> 89.49238 | H8: 0 | I8: =H8 -> 0 | J8: 0 | K8: =J8 -> 0 | M8: CPU
B9: 研发费用汇总 | C9: =SUM(C3:C8) -> 4740550 | E9: 物流（工厂到仓库）/unit | F9: 0 | G9: =F9/1.09 -> 0 | H9: =F9 -> 0 | I9: =H9/1.09 -> 0 | J9: =H9 -> 0 | K9: =J9/1.09 -> 0 | M9: Volumn （3years) | N9: =SUM(C20:C26) -> 108000
E10: 物流（仓库到用户）/unit | F10: 0.58 | G10: =F10/1.09 -> 0.53211009 | H10: =F10 -> 0.58 | I10: =H10/1.09 -> 0.53211009 | J10: =H10 -> 0.58 | K10: =J10/1.09 -> 0.53211009 | M10: Revenue | N10: =G28+I28+K28 -> 53082400
B11: Royalty（Airprint) | C11: 0 | E11: Logistics Cost | F11: =F10+F9 -> 0.58 | G11: =G10+G9 -> 0.53211009 | H11: =H10+H9 -> 0.58 | I11: =I10+I9 -> 0.53211009 | J11: =J10+J9 -> 0.58 | K11: =K10+K9 -> 0.53211009 | M11: GM | N11: =G23*G27+I23*I27+K23*K27 -> 29663285
B12: Royalty（GGS) | C12: 0 | E12: 汉图MOH比例 | F12: 0.05 | G12: =F12 -> 0.05 | H12: 0.05 | I12: =H12 -> 0.05 | J12: 0.05 | K12: =J12 -> 0.05 | M12: GM% | N12: =N11/N10 -> 0.55881582
B13: Royalty（Adobe) | C13: 0 | E13: 汉图MOH | F13: =F12*F5 -> 12.5 | G13: =F13 -> 12.5 | H13: =H12*H5 -> 12.25 | I13: =H13 -> 12.25 | J13: =J12*J5 -> 12.005 | K13: =J13 -> 12.005 | M13: Profit | N13: =G29+I29+K29 -> 5554014
B14: Royalty（WPS) | C14: 0 | E14: 返修率 | F14: 0.017 | G14: =F14 -> 0.017 | H14: =F14 -> 0.017 | I14: =H14 -> 0.017 | J14: =F14 -> 0.017 | K14: =J14 -> 0.017 | M14: Profit % | N14: =N13/N10 -> 0.10463005
B15: Royalty (Others) | C15: 0 | E15: 返修费用 | F15: =C28*F14 -> 4.25 | G15: =F15/1.13 -> 3.7610619 | H15: =H14*C28 -> 4.25 | I15: =H15/1.13 -> 3.7610619 | J15: =J14*C28 -> 4.25 | K15: =J15/1.13 -> 3.7610619 | M15: Investment | N15: =C9 -> 4740550
B16: Royalty (Total) | C16: =SUM(C11:C15) -> 0 | E16: Service Cost | F16: =F15 -> 4.25 | G16: =G15 -> 3.7610619 | H16: =H15 -> 4.25 | I16: =I15 -> 3.7610619 | J16: =J15 -> 4.25 | K16: =K15 -> 3.7610619 | M16: ROI | N16: =N13/N15 -> 1.171597
B17: OS | C17: 0 | E17: 资金成本率 | F17: 0.005 | G17: 0.01 | H17: 0.005 | I17: 0.01 | J17: 0.005 | K17: 0.01
E18: 资金成本 | F18: =F5*F17 -> 1.25 | G18: =F18 -> 1.25 | H18: =H5*H17 -> 1.225 | I18: =H18 -> 1.225 | J18: =J5*J17 -> 1.2005 | K18: =J18 -> 1.2005
B19: 生态链单机 | E19: 销售费用% | F19: 0.3 | G19: 0.01 | H19: 0.3 | I19: 0.01 | J19: 0.3 | K19: 0.01
B20: 第一年销量（国内） | C20: =Scenarios!C12 -> 36000 | E20: 销售费用/unit | F20: =F19*F22 -> 170.59095 | G20: =F20 -> 170.59095 | H20: =H19*H22 -> 166.29713 | I20: =H20 -> 166.29713 | J20: =J19*J22 -> 162.97119 | K20: =J20 -> 162.97119 | M20: =F20*C20+H20*C21+J20*C22 -> 17994934
B21: 第二年销量（国内） | C21: =Scenarios!C13 -> 36000 | E21: Total COS | F21: =F5+F6++F7+F8+F11+F13+F16+F18+F20 -> 570.85289 | G21: =G5+G6++G7+G8+G11+G13+G16+G18+G20 -> 526.40575 | H21: =H5+H6++H7+H8+H11+H13+H16+H18+H20 -> 429.60213 | I21: =I5+I6++I7+I8+I11+I13+I16+I18+I20 -> 400.87946 | J21: =J5+J6++J7+J8+J11+J13+J16+J18+J20 -> 421.10669 | K21: =K5+K6++K7+K8+K11+K13+K16+K18+K20 -> 392.94774
B22: 第三年销量（国内） | C22: =Scenarios!C14 -> 36000 | E22: 收入 | F22: ='BOM&ASP'!C10 -> 568.6365 | G22: =F22/1.13 -> 503.21814 | H22: =(F22-3)*0.98 -> 554.32377 | I22: =H22/1.13 -> 490.55201 | J22: =H22*0.98 -> 543.23729 | K22: =J22/1.13 -> 480.74097
E23: 毛利/unit（含税） | F23: =F22-F5 -> 318.6365 | G23: =G22-G5 -> 281.9792 | H23: =H22-H5 -> 309.32377 | I23: =I22-I5 -> 273.73785 | J23: =J22-J5 -> 303.13729 | K23: =K22-K5 -> 268.26309
B24: 第一年销量（海外） | C24: 0 | E24: 毛利率 | F24: =F23/F22 -> 0.56035182 | G24: =G23/G22 -> 0.56035182 | H24: =H23/H22 -> 0.55802004 | I24: =I23/I22 -> 0.55802004 | J24: =J23/J22 -> 0.55802004 | K24: =K23/K22 -> 0.55802004
B25: 第二年销量（海外） | C25: 0 | E25: 净利/unit（含税） | F25: =F22-F21 -> -2.2163944 | G25: =G22-G21 -> -23.187613 | H25: =H22-H21 -> 124.72164 | I25: =I22-I21 -> 89.672547 | J25: =J22-J21 -> 122.13061 | K25: =K22-K21 -> 87.793232
B26: 第三年销量（海外） | C26: 0 | E26: 净利率 | F26: =F25/F22 -> -0.0038977351 | G26: =G25/G22 -> -0.04607865 | H26: =H25/H22 -> 0.22499782 | I26: =I25/I22 -> 0.18279926 | J26: =J25/J22 -> 0.22482 | K26: =K25/K22 -> 0.18262066
E27: Volumn | F27: =C20+C24 -> 36000 | G27: =F27 -> 36000 | H27: =C21+C25 -> 36000 | I27: =H27 -> 36000 | J27: =C22+C26 -> 36000 | K27: =J27 -> 36000
B28: 返修成本HW（含税） | C28: =F5 -> 250 | E28: 总收入 | F28: =F27*F22 -> 20470914 | G28: =G27*G22 -> 18115853 | H28: =H27*H22 -> 19955656 | I28: =I27*I22 -> 17659872 | J28: =J27*J22 -> 19556543 | K28: =K27*K22 -> 17306675
E29: 总净利 | F29: =F27*F25 -> -79790.2 | G29: =G27*G25 -> -834754.06 | H29: =H27*H25 -> 4489979 | I29: =I27*I25 -> 3228211.7 | J29: =J27*J25 -> 4396701.8 | K29: =K27*K25 -> 3160556.4

Sheet Worst Secnario
B1: AiKen Worst Scenario
B3: 模具 | C3: =Budget!H3 -> 600000 | F3: YEAR 1 | H3: YEAR 2 | J3: YEAR 3 | M3: Worst
B4: 治具 | C4: =Budget!H4 -> 500000 | F4: 含税 | G4: 不含税 | H4: 含税 | I4: 不含税 | J4: 含税 | K4: 不含税 | N4: 主机（不含税）
B5: 研发NRE (含CCOW) | C5: =Budget!H5 -> 375550 | E5: MPC（出厂价） | F5: ='BOM&ASP'!F3 -> 250 | G5: =F5/1.13 -> 221.23894 | H5: =F5*0.98 -> 245 | I5: =H5/1.13 -> 216.81416 | J5: =H5*0.98 -> 240.1 | K5: =J5/1.13 -> 212.47788 | M5: Hannto零售价 | N5: =G22 -> 503.21814
B6: 测试 | C6: =Budget!H6 -> 145000 | E6: Royalty, License, Usage/unit | F6: =$C$16+$C$17 -> 0 | G6: =F6 -> 0 | H6: =$C$16+$C$17 -> 0 | I6: =H6 -> 0 | J6: =$C$16+$C$17 -> 0 | K6: =J6 -> 0 | M6: Hannto毛利率 | N6: =(N5-N7)/N5 -> 0.56035182
B7: 认证 | C7: =Budget!H7 -> 150000 | E7: 模具治具摊销/unit | F7: =(C3+C4-D3)/C20 -> 76.388889 | G7: =F7/1.13 -> 67.600787 | H7: 0 | I7: =H7/1.13 -> 0 | J7: 0 | K7: =J7/1.13 -> 0 | M7: MPC | N7: =G5 -> 221.23894
B8: 其他 | C8: =Budget!H8 -> 2970000 | E8: 研发费用摊销/unit | F8: =(C9-C3-C4)/C20 -> 252.81597 | G8: =F8/1.13 -> 223.73095 | H8: 0 | I8: =H8 -> 0 | J8: 0 | K8: =J8 -> 0 | M8: CPU
B9: 研发费用汇总 | C9: =SUM(C3:C8) -> 4740550 | E9: 物流（工厂到仓库）/unit | F9: 0 | G9: =F9/1.09 -> 0 | H9: =F9 -> 0 | I9: =H9/1.09 -> 0 | J9: =H9 -> 0 | K9: =J9/1.09 -> 0 | M9: Volumn （3years) | N9: =SUM(C20:C26) -> 43200
E10: 物流（仓库到用户）/unit | F10: 0.58 | G10: =F10/1.09 -> 0.53211009 | H10: =F10 -> 0.58 | I10: =H10/1.09 -> 0.53211009 | J10: =H10 -> 0.58 | K10: =J10/1.09 -> 0.53211009 | M10: Revenue | N10: =G28+I28+K28 -> 21232960
B11: Royalty（Airprint) | C11: 0 | E11: Logistics Cost | F11: =F10+F9 -> 0.58 | G11: =G10+G9 -> 0.53211009 | H11: =H10+H9 -> 0.58 | I11: =I10+I9 -> 0.53211009 | J11: =J10+J9 -> 0.58 | K11: =K10+K9 -> 0.53211009 | M11: GM | N11: =G23*G27+I23*I27+K23*K27 -> 11865314
B12: Royalty（GGS) | C12: 0 | E12: 汉图MOH比例 | F12: 0.05 | G12: =F12 -> 0.05 | H12: 0.05 | I12: =H12 -> 0.05 | J12: 0.05 | K12: =J12 -> 0.05 | M12: GM% | N12: =N11/N10 -> 0.55881582
B13: Royalty（Adobe) | C13: 0 | E13: 汉图MOH | F13: =F12*F5 -> 12.5 | G13: =F13 -> 12.5 | H13: =H12*H5 -> 12.25 | I13: =H13 -> 12.25 | J13: =J12*J5 -> 12.005 | K13: =J13 -> 12.005 | M13: Profit | N13: =G29+I29+K29 -> -295500.6
B14: Royalty（WPS) | C14: 0 | E14: 返修率 | F14: 0.017 | G14: =F14 -> 0.017 | H14: =F14 -> 0.017 | I14: =H14 -> 0.017 | J14: =F14 -> 0.017 | K14: =J14 -> 0.017 | M14: Profit % | N14: =N13/N10 -> -0.013917071
B15: Royalty (Others) | C15: 0 | E15: 返修费用 | F15: =C28*F14 -> 4.25 | G15: =F15/1.13 -> 3.7610619 | H15: =H14*C28 -> 4.25 | I15: =H15/1.13 -> 3.7610619 | J15: =J14*C28 -> 4.25 | K15: =J15/1.13 -> 3.7610619 | M15: Investment | N15: =C9 -> 4740550
B16: Royalty (Total) | C16: =SUM(C11:C15) -> 0 | E16: Service Cost | F16: =F15 -> 4.25 | G16: =G15 -> 3.7610619 | H16: =H15 -> 4.25 | I16: =I15 -> 3.7610619 | J16: =J15 -> 4.25 | K16: =K15 -> 3.7610619 | M16: ROI | N16: =N13/N15 -> -0.062334667
B17: OS | C17: 0 | E17: 资金成本率 | F17: 0.005 | G17: 0.01 | H17: 0.005 | I17: 0.01 | J17: 0.005 | K17: 0.01
E18: 资金成本 | F18: =F5*F17 -> 1.25 | G18: =F18 -> 1.25 | H18: =H5*H17 -> 1.225 | I18: =H18 -> 1.225 | J18: =J5*J17 -> 1.2005 | K18: =J18 -> 1.2005
B19: 生态链单机 | E19: 销售费用% | F19: 0.3 | G19: 0.01 | H19: 0.3 | I19: 0.01 | J19: 0.3 | K19: 0.01
B20: 第一年销量（国内） | C20: =Scenarios!C20 -> 14400 | E20: 销售费用/unit | F20: =F19*F22 -> 170.59095 | G20: =F20 -> 170.59095 | H20: =H19*H22 -> 166.29713 | I20: =H20 -> 166.29713 | J20: =J19*J22 -> 162.97119 | K20: =J20 -> 162.97119 | M20: =F20*C20+H20*C21+J20*C22 -> 7197973.5
B21: 第二年销量（国内） | C21: =Scenarios!C21 -> 14400 | E21: Total COS | F21: =F5+F6++F7+F8+F11+F13+F16+F18+F20 -> 768.37581 | G21: =G5+G6++G7+G8+G11+G13+G16+G18+G20 -> 701.2048 | H21: =H5+H6++H7+H8+H11+H13+H16+H18+H20 -> 429.60213 | I21: =I5+I6++I7+I8+I11+I13+I16+I18+I20 -> 400.87946 | J21: =J5+J6++J7+J8+J11+J13+J16+J18+J20 -> 421.10669 | K21: =K5+K6++K7+K8+K11+K13+K16+K18+K20 -> 392.94774
B22: 第三年销量（国内） | C22: =Scenarios!C22 -> 14400 | E22: 收入 | F22: ='BOM&ASP'!C10 -> 568.6365 | G22: =F22/1.13 -> 503.21814 | H22: =(F22-3)*0.98 -> 554.32377 | I22: =H22/1.13 -> 490.55201 | J22: =H22*0.98 -> 543.23729 | K22: =J22/1.13 -> 480.74097
E23: 毛利/unit（含税） | F23: =F22-F5 -> 318.6365 | G23: =G22-G5 -> 281.9792 | H23: =H22-H5 -> 309.32377 | I23: =I22-I5 -> 273.73785 | J23: =J22-J5 -> 303.13729 | K23: =K22-K5 -> 268.26309
B24: 第一年销量（海外） | C24: 0 | E24: 毛利率 | F24: =F23/F22 -> 0.56035182 | G24: =G23/G22 -> 0.56035182 | H24: =H23/H22 -> 0.55802004 | I24: =I23/I22 -> 0.55802004 | J24: =J23/J22 -> 0.55802004 | K24: =K23/K22 -> 0.55802004
B25: 第二年销量（海外） | C25: 0 | E25: 净利/unit（含税） | F25: =F22-F21 -> -199.73931 | G25: =G22-G21 -> -197.98665 | H25: =H22-H21 -> 124.72164 | I25: =I22-I21 -> 89.672547 | J25: =J22-J21 -> 122.13061 | K25: =K22-K21 -> 87.793232
B26: 第三年销量（海外） | C26: 0 | E26: 净利率 | F26: =F25/F22 -> -0.3512601 | G26: =G25/G22 -> -0.39344101 | H26: =H25/H22 -> 0.22499782 | I26: =I25/I22 -> 0.18279926 | J26: =J25/J22 -> 0.22482 | K26: =K25/K22 -> 0.18262066
E27: Volumn | F27: =C20+C24 -> 14400 | G27: =F27 -> 14400 | H27: =C21+C25 -> 14400 | I27: =H27 -> 14400 | J27: =C22+C26 -> 14400 | K27: =J27 -> 14400
B28: 返修成本HW（含税） | C28: =F5 -> 250 | E28: 总收入 | F28: =F27*F22 -> 8188365.6 | G28: =G27*G22 -> 7246341.2 | H28: =H27*H22 -> 7982262.3 | I28: =I27*I22 -> 7063948.9 | J28: =J27*J22 -> 7822617 | K28: =K27*K22 -> 6922669.9
E29: 总净利 | F29: =F27*F25 -> -2876246.1 | G29: =G27*G25 -> -2851007.8 | H29: =H27*H25 -> 1795991.6 | I29: =I27*I25 -> 1291284.7 | J29: =J27*J25 -> 1758680.7 | K29: =K27*K25 -> 1264222.5

Sheet 销量概率分布说明
B2: AiKen 销量概率分布 · 读数表
B3: 模型 v0.3 · 8,000 次蒙特卡洛 · 漏斗参数已按 S1 实测校准（CPM 37.6/45.2 · CTR 2.14% · CVR 0.98%；数据源：极印投放数据 2026-10-26）
B5: 这个分布是什么？ | C5: 8,000 次模拟得到的「首年（或三年累计）销量」的全集。每次模拟 = 从参照类先验区间随机抽一组 (m·p·q) 跑一条 Bass 曲线。它不是正态分布——右尾更长（小概率卖出非常多），形状类似对数正态。
B6: 横轴 / 纵轴各是什么？ | C6: 横轴 = 销量（台）；纵轴 = 概率密度（落在这个销量区间的模拟次数占比）。曲线下总面积 = 100%。
B7: P5 / P50 / P95 是什么？ | C7: 分位数。P50 = 中位数：一半的模拟结果比它高、一半比它低（最可能的单点读数）。P5 = 只有 5% 的模拟比它更差（悲观边界）；P95 = 只有 5% 的模拟比它更好（乐观边界）。P5–P95 之间覆盖了 90% 的可能性，即「大概率区间」。
B8: 怎么读「达到某销量对应多少概率」？ | C8: 两种读法：① 找分位表中第一个 ≥ 该销量的行，其概率列即答案（近似）；② 直接查「关键概率」表——如 P(首年 ≥ 3.6万) 表示 8,000 次模拟中销量 ≥ 36,000 台的次数占比。注意：分位表给的是「多少分位对应多少销量」，关键概率表给的是「多少销量对应多少概率」，两者互为反查。
B9: 和三档场景（Worst/Normal/Best）什么关系？ | C9: 三档场景 = 分布上的分位锚，不是预测点：Worst（月销500→年6000）≈ P1 以下；Normal（月销1000→年1.2万）≈ P1；Best（月销3000→年3.6万）≈ P75。三档供供应链与财务执行使用；全分布才是决策工具（详见方法论说明页）。
B10: 为什么首年 P50（2.86万）比会议 Normal（1.2万）高？ | C10: 主要差异来自媒介预算假设：模型按上市前 6 个月 120–280 万投放测算（P50≈202万），而会议 Normal 按 2% 销售费用折算全年仅约 14 万。校准会已确认 2% 不够——预算口径待市场部确认后重跑 v0.3。
B11: 读数示例 | C11: 「首年销量 P50 = 28,600 台」→ 一半的可能性卖得比它多；「P(首年 ≥ 36,000) = 25.8%」→ 约四分之一的概率达到 Best 档；「三年累计 P95 = 158,000 台」→ 20 次里约有 1 次三年卖过 15.8 万台。

Sheet RCF数值
B2: m · 市场潜力（36 个月累计销量上限，对数正态分布，中位数 12 万、σ=0.90）
B3: 统计量 | C3: 数值
B4: P50（最可能值） | C4: 12.06 万台
B5: P10 | C5: 3.86 万台
B6: P90 | C6: 36.83 万台
B7: P5 / P95 | C7: 2.92 万 / 50.54 万台
B8: 8000 次抽样的实际最小值 | C8: 0.52 万台
B9: 8000 次抽样的实际最大值 | C9: 493.8 万台
B10: P(≥100 万台) | C10: 0.0103
B11: 注：对数正态分布理论上无上下界（右尾无限延伸），上面的「实际最小/最大值」只是这一次 8000 次抽样碰到的边界。
B13: q · 口碑系数（正态分布 μ=0.42、σ=0.10，硬截断在 [0.18, 0.68]）
B14: 统计量 | C14: 数值
B15: P50（最可能值） | C15: 0.419
B16: P10 | C16: 0.291
B17: P90 | C17: 0.547
B18: P5 / P95 | C18: 0.254 / 0.583
B19: 硬下限 / 硬上限 | C19: 0.18 / 0.68
B20: 注：截断把极端尾巴切掉了（下界堆积 0.9%、上界 0.4% 的样本），下限 0.18 对应「口碑几乎不起作用」的保守情形，上限 0.68 对应 instax/CCD 级别的强传染。
B22: 依据等级：
B23: m 的中位数 12 万和 q 的 0.42 是基于参照类（instax mini 中国盘、Flashback、Kodak Mini Shot 年销 1–3 万、CCD 潮流信号）+ 薇娅 6600 台脉冲证据做的推断校准，不是极印实测——页面页脚也标了「待市场部数据校准」。N3/S1 的首发曲线到位后，这两个先验会向极印自身能力基线收窄。
